Workbook

Sheet Tabla_records
A1: Edad | B1: Sexo | C1: DIstancia
A2: jr | B2: f | C2: 500
A3: sr | B3: m | C3: 1000
C4: 1500
C5: 3000
C6: 5000
C7: 10000

Sheet Competición más reciente
A1: INDICE | B1: Nombre patinador | C1: ID | D1: Edad final temporada | E1: Nacimiento | F1: Sexo | G1: Category | H1: Competicion mas reciente | I1: Fecha fin | J1: Lugar | K1: Enlace | L1: Enlace
B2: Abril del Río Calonge | C2: 114671 | D2: 23 | E2: 37724 | F2: F | G2: LN4 | H2: NK Clubs 2026 | I2: 46299 | J2: Heerenveen (NED) | K2: http://speedskatingresults.com/index.php?p=2&e=32120&s=114671
A3: Informacion obtenida de: | B3: Ona Rodríguez Cornejo | C3: 79811 | D3: 18 | E3: 39429 | F3: F | G3: LA1 | H3: International Thialf Race | I3: 46292 | J3: Heerenveen (NED) | K3: http://speedskatingresults.com/index.php?p=2&e=32109&s=79811
A4: https://speedskatingresults.com/ | B4: Sergi Álvarez Fernández | C4: 63475 | D4: 18 | E4: 39427 | F4: M | G4: MA1
B5: Francisco Aparicio Navarro | C5: 55766 | D5: 41 | E5: 31017 | F5: M | G5: M40
A6: Temporada | B6: Stéphane Barbera Peraleda | C6: 60818 | D6: 26 | E6: 36677 | F6: M | G6: MSA
A7: 2024-2025 | B7: Marcello Bresin | C7: 13213 | D7: 56 | E7: 25538 | F7: M | G7: M55
B8: Nil Cañizares Rentero | C8: 63474 | D8: 18 | E8: 39264 | F8: M | G8: MA1
B9: Pau Chorro Luque | C9: 90376 | D9: 22 | E9: 37803 | F9: M | G9: MN3
B10: Iñigo Vidondo Fernández de Larrinoa | C10: 41638 | D10: 37 | E10: 32621 | F10: M | G10: M35
B11: Adriá Fernández Torres | C11: 109334 | D11: 16 | E11: 39995 | F11: M | G11: MB1
B12: Jorge Fernández Cantero | C12: 47297 | D12: 35 | E12: 33343 | F12: M | G12: M35
B13: Gonzalo Ferraz García | C13: 106984 | D13: 23 | E13: 37446 | F13: M | G13: MN4
B14: Ramón Franquesa | C14: 109837 | D14: 96 | E14: 10959 | F14: M | G14: M+
B15: Sergio Borja García García | C15: 93677 | D15: 28 | E15: 35674 | F15: M | G15: MSA
B16: Daniel Garro Martínez | C16: 99863 | D16: 22 | E16: 37820 | F16: M | G16: MN3
B17: Antonio Gómez Fernández | C17: 626 | D17: 83 | E17: 15738 | F17: M | G17: M+
B18: Samuel Granada García | C18: 116539 | D18: 15 | E18: 40639 | F18: M | G18: MC2
B19: Jhoan Sebastián Guzmán Bitar | C19: 101840 | D19: 30 | E19: 35004 | F19: M | G19: M30
... B78: Natalia Vidal Ponce | C78: 69314 | D78: 29 | E78: 35278 | F78: F | G78: LSA

Sheet Última carrera por temporada
C1: Nombre | D1: Speedskating Id | E1: URL | F1: Edad final temporada | G1: Nacimiento | H1: Fecha carrera aux | I1: Sexo | J1: Category | K1: Skater | L1: Season | M1: Competitions Id | N1: Competitions Name | O1: Competitions Startdate | P1: Competitions Enddate | Q1: Competitions Location | R1: Competitions Trackid | S1: Competitions Link
C2: =#REF! -> #REF! | D2: =#REF! -> #REF! | E2: =CONCATENATE("https://speedskatingresults.com/api/json/skater_competitions?skater=",D2,"&season=",$B$6) -> #REF! | F2: =IF(ISBLANK(N2)," ",IF( YEARFRAC(G2,CONCATENATE("31/12/",YEAR(G2)),1)>0.502, ROUND(YEARFRAC(CONCATENATE("31/12/",YEAR(G2)-1),IF( YEARFRAC(H2,CONCATENATE("31/12/",YEAR(H2)),1)>0.502, CONCATENATE("31/12/",YEAR(H2)-1), CONCATENATE("31/12/",YEAR(H2)) ),1),0), ROUND(YEARFRAC(CONCATENATE("31/12/",YEAR(G2)),IF( YEARFRAC(H2,CONCATENATE("31/12/",YEAR(H2)),1)>0.502, CONCATENATE("31/12/",YEAR(H2)-1), CONCATENATE("31/12/",YEAR(H2)) ),1),0) )) -> #NAME? | G2: {=IF(ISBLANK(N2)," ",_xlfn.XLOOKUP(D2,#REF!,#REF!))} -> #NAME? | H2: =O2 -> 2026-02-27 | I2: {=IF(ISBLANK(K2)," ",_xlfn.XLOOKUP(D2,#REF!,#REF!))} -> #NAME? | J2: {=IF(ISBLANK(N2)," ",_xlfn.XLOOKUP(F2,Edades!$A$2:$A$101,IF(I2="F",Edades!$B$2:$B$101,Edades!$C$2:$C$101)))} -> #NAME? | K2: =IFERROR(__xludf.DUMMYFUNCTION("index(query(importjson(E2)),2,)"),"93128") -> 93128 | L2: =IFERROR(__xludf.DUMMYFUNCTION("""COMPUTED_VALUE"""),"2025") -> 2025 | M2: =IFERROR(__xludf.DUMMYFUNCTION("""COMPUTED_VALUE"""),"31773") -> 31773 | N2: =IFERROR(__xludf.DUMMYFUNCTION("""COMPUTED_VALUE"""),"ISU Junior World Championships 2026") -> ISU Junior World Championships 2026 | O2: =IFERROR(__xludf.DUMMYFUNCTION("""COMPUTED_VALUE"""),"2026-02-27") -> 2026-02-27 | P2: =IFERROR(__xludf.DUMMYFUNCTION("""COMPUTED_VALUE"""),"2026-03-01") -> 2026-03-01 | Q2: =IFERROR(__xludf.DUMMYFUNCTION("""COMPUTED_VALUE"""),"Inzell (GER)") -> Inzell (GER) | R2: =IFERROR(__xludf.DUMMYFUNCTION("""COMPUTED_VALUE"""),"11") -> 11 | S2: =IFERROR(__xludf.DUMMYFUNCTION("""COMPUTED_VALUE"""),"http://speedskatingresults.com/index.php?p=2&e=31773&s=93128") -> http://speedskatingresults.com/index.php?p=2&e=31773&s=93128
C3: =#REF! -> #REF! | D3: =#REF! -> #REF! | E3: =CONCATENATE("https://speedskatingresults.com/api/json/skater_competitions?skater=",D3,"&season=",$B$6) -> #REF! | F3: =IF(ISBLANK(N3)," ",IF( YEARFRAC(G3,CONCATENATE("31/12/",YEAR(G3)),1)>0.502, ROUND(YEARFRAC(CONCATENATE("31/12/",YEAR(G3)-1),IF( YEARFRAC(H3,CONCATENATE("31/12/",YEAR(H3)),1)>0.502, CONCATENATE("31/12/",YEAR(H3)-1), CONCATENATE("31/12/",YEAR(H3)) ),1),0), ROUND(YEARFRAC(CONCATENATE("31/12/",YEAR(G3)),IF( YEARFRAC(H3,CONCATENATE("31/12/",YEAR(H3)),1)>0.502, CONCATENATE("31/12/",YEAR(H3)-1), CONCATENATE("31/12/",YEAR(H3)) ),1),0) )) | G3: {=IF(ISBLANK(N3)," ",_xlfn.XLOOKUP(D3,#REF!,#REF!))} | H3: =O3 -> 0 | I3: {=IF(ISBLANK(K3)," ",_xlfn.XLOOKUP(D3,#REF!,#REF!))} | J3: {=IF(ISBLANK(N3)," ",_xlfn.XLOOKUP(F3,Edades!$A$2:$A$101,IF(I3="F",Edades!$B$2:$B$101,Edades!$C$2:$C$101)))}
C4: =#REF! -> #REF! | D4: =#REF! -> #REF! | E4: =CONCATENATE("https://speedskatingresults.com/api/json/skater_competitions?skater=",D4,"&season=",$B$6) -> #REF! | F4: =IF(ISBLANK(N4)," ",IF( YEARFRAC(G4,CONCATENATE("31/12/",YEAR(G4)),1)>0.502, ROUND(YEARFRAC(CONCATENATE("31/12/",YEAR(G4)-1),IF( YEARFRAC(H4,CONCATENATE("31/12/",YEAR(H4)),1)>0.502, CONCATENATE("31/12/",YEAR(H4)-1), CONCATENATE("31/12/",YEAR(H4)) ),1),0), ROUND(YEARFRAC(CONCATENATE("31/12/",YEAR(G4)),IF( YEARFRAC(H4,CONCATENATE("31/12/",YEAR(H4)),1)>0.502, CONCATENATE("31/12/",YEAR(H4)-1), CONCATENATE("31/12/",YEAR(H4)) ),1),0) )) -> #NAME? | G4: {=IF(ISBLANK(N4)," ",_xlfn.XLOOKUP(D4,#REF!,#REF!))} -> #NAME? | H4: =O4 -> 2026-02-27 | I4: {=IF(ISBLANK(K4)," ",_xlfn.XLOOKUP(D4,#REF!,#REF!))} -> #NAME? | J4: {=IF(ISBLANK(N4)," ",_xlfn.XLOOKUP(F4,Edades!$A$2:$A$101,IF(I4="F",Edades!$B$2:$B$101,Edades!$C$2:$C$101)))} -> #NAME? | K4: =IFERROR(__xludf.DUMMYFUNCTION("INDEX(query(importjson(E4)),2,)"),"63475") -> 63475 | L4: =IFERROR(__xludf.DUMMYFUNCTION("""COMPUTED_VALUE"""),"2025") -> 2025 | M4: =IFERROR(__xludf.DUMMYFUNCTION("""COMPUTED_VALUE"""),"31773") -> 31773 | N4: =IFERROR(__xludf.DUMMYFUNCTION("""COMPUTED_VALUE"""),"ISU Junior World Championships 2026") -> ISU Junior World Championships 2026 | O4: =IFERROR(__xludf.DUMMYFUNCTION("""COMPUTED_VALUE"""),"2026-02-27") -> 2026-02-27 | P4: =IFERROR(__xludf.DUMMYFUNCTION("""COMPUTED_VALUE"""),"2026-03-01") -> 2026-03-01 | Q4: =IFERROR(__xludf.DUMMYFUNCTION("""COMPUTED_VALUE"""),"Inzell (GER)") -> Inzell (GER) | R4: =IFERROR(__xludf.DUMMYFUNCTION("""COMPUTED_VALUE"""),"11") -> 11 | S4: =IFERROR(__xludf.DUMMYFUNCTION("""COMPUTED_VALUE"""),"http://speedskatingresults.com/index.php?p=2&e=31773&s=63475") -> http://speedskatingresults.com/index.php?p=2&e=31773&s=63475
B5: Año primero temporada | C5: =#REF! -> #REF! | D5: =#REF! -> #REF! | E5: =CONCATENATE("https://speedskatingresults.com/api/json/skater_competitions?skater=",D5,"&season=",$B$6) -> #REF! | F5: =IF(ISBLANK(N5)," ",IF( YEARFRAC(G5,CONCATENATE("31/12/",YEAR(G5)),1)>0.502, ROUND(YEARFRAC(CONCATENATE("31/12/",YEAR(G5)-1),IF( YEARFRAC(H5,CONCATENATE("31/12/",YEAR(H5)),1)>0.502, CONCATENATE("31/12/",YEAR(H5)-1), CONCATENATE("31/12/",YEAR(H5)) ),1),0), ROUND(YEARFRAC(CONCATENATE("31/12/",YEAR(G5)),IF( YEARFRAC(H5,CONCATENATE("31/12/",YEAR(H5)),1)>0.502, CONCATENATE("31/12/",YEAR(H5)-1), CONCATENATE("31/12/",YEAR(H5)) ),1),0) )) | G5: {=IF(ISBLANK(N5)," ",_xlfn.XLOOKUP(D5,#REF!,#REF!))} | H5: =O5 -> 0 | I5: {=IF(ISBLANK(K5)," ",_xlfn.XLOOKUP(D5,#REF!,#REF!))} | J5: {=IF(ISBLANK(N5)," ",_xlfn.XLOOKUP(F5,Edades!$A$2:$A$101,IF(I5="F",Edades!$B$2:$B$101,Edades!$C$2:$C$101)))}
B6: 2025 | C6: =#REF! -> #REF! | D6: =#REF! -> #REF! | E6: =CONCATENATE("https://speedskatingresults.com/api/json/skater_competitions?skater=",D6,"&season=",$B$6) -> #REF! | F6: =IF(ISBLANK(N6)," ",IF( YEARFRAC(G6,CONCATENATE("31/12/",YEAR(G6)),1)>0.502, ROUND(YEARFRAC(CONCATENATE("31/12/",YEAR(G6)-1),IF( YEARFRAC(H6,CONCATENATE("31/12/",YEAR(H6)),1)>0.502, CONCATENATE("31/12/",YEAR(H6)-1), CONCATENATE("31/12/",YEAR(H6)) ),1),0), ROUND(YEARFRAC(CONCATENATE("31/12/",YEAR(G6)),IF( YEARFRAC(H6,CONCATENATE("31/12/",YEAR(H6)),1)>0.502, CONCATENATE("31/12/",YEAR(H6)-1), CONCATENATE("31/12/",YEAR(H6)) ),1),0) )) | G6: {=IF(ISBLANK(N6)," ",_xlfn.XLOOKUP(D6,#REF!,#REF!))} | H6: =O6 -> 0 | I6: {=IF(ISBLANK(K6)," ",_xlfn.XLOOKUP(D6,#REF!,#REF!))} | J6: {=IF(ISBLANK(N6)," ",_xlfn.XLOOKUP(F6,Edades!$A$2:$A$101,IF(I6="F",Edades!$B$2:$B$101,Edades!$C$2:$C$101)))}
C7: =#REF! -> #REF! | D7: =#REF! -> #REF! | E7: =CONCATENATE("https://speedskatingresults.com/api/json/skater_competitions?skater=",D7,"&season=",$B$6) -> #REF! | F7: =IF(ISBLANK(N7)," ",IF( YEARFRAC(G7,CONCATENATE("31/12/",YEAR(G7)),1)>0.502, ROUND(YEARFRAC(CONCATENATE("31/12/",YEAR(G7)-1),IF( YEARFRAC(H7,CONCATENATE("31/12/",YEAR(H7)),1)>0.502, CONCATENATE("31/12/",YEAR(H7)-1), CONCATENATE("31/12/",YEAR(H7)) ),1),0), ROUND(YEARFRAC(CONCATENATE("31/12/",YEAR(G7)),IF( YEARFRAC(H7,CONCATENATE("31/12/",YEAR(H7)),1)>0.502, CONCATENATE("31/12/",YEAR(H7)-1), CONCATENATE("31/12/",YEAR(H7)) ),1),0) )) | G7: {=IF(ISBLANK(N7)," ",_xlfn.XLOOKUP(D7,#REF!,#REF!))} | H7: =O7 -> 0 | I7: {=IF(ISBLANK(K7)," ",_xlfn.XLOOKUP(D7,#REF!,#REF!))} | J7: {=IF(ISBLANK(N7)," ",_xlfn.XLOOKUP(F7,Edades!$A$2:$A$101,IF(I7="F",Edades!$B$2:$B$101,Edades!$C$2:$C$101)))}
C8: =#REF! -> #REF! | D8: =#REF! -> #REF! | E8: =CONCATENATE("https://speedskatingresults.com/api/json/skater_competitions?skater=",D8,"&season=",$B$6) -> #REF! | F8: =IF(ISBLANK(N8)," ",IF( YEARFRAC(G8,CONCATENATE("31/12/",YEAR(G8)),1)>0.502, ROUND(YEARFRAC(CONCATENATE("31/12/",YEAR(G8)-1),IF( YEARFRAC(H8,CONCATENATE("31/12/",YEAR(H8)),1)>0.502, CONCATENATE("31/12/",YEAR(H8)-1), CONCATENATE("31/12/",YEAR(H8)) ),1),0), ROUND(YEARFRAC(CONCATENATE("31/12/",YEAR(G8)),IF( YEARFRAC(H8,CONCATENATE("31/12/",YEAR(H8)),1)>0.502, CONCATENATE("31/12/",YEAR(H8)-1), CONCATENATE("31/12/",YEAR(H8)) ),1),0) )) | G8: {=IF(ISBLANK(N8)," ",_xlfn.XLOOKUP(D8,#REF!,#REF!))} | H8: =O8 -> 0 | I8: {=IF(ISBLANK(K8)," ",_xlfn.XLOOKUP(D8,#REF!,#REF!))} | J8: {=IF(ISBLANK(N8)," ",_xlfn.XLOOKUP(F8,Edades!$A$2:$A$101,IF(I8="F",Edades!$B$2:$B$101,Edades!$C$2:$C$101)))}
C9: =#REF! -> #REF! | D9: =#REF! -> #REF! | E9: =CONCATENATE("https://speedskatingresults.com/api/json/skater_competitions?skater=",D9,"&season=",$B$6) -> #REF! | F9: =IF(ISBLANK(N9)," ",IF( YEARFRAC(G9,CONCATENATE("31/12/",YEAR(G9)),1)>0.502, ROUND(YEARFRAC(CONCATENATE("31/12/",YEAR(G9)-1),IF( YEARFRAC(H9,CONCATENATE("31/12/",YEAR(H9)),1)>0.502, CONCATENATE("31/12/",YEAR(H9)-1), CONCATENATE("31/12/",YEAR(H9)) ),1),0), ROUND(YEARFRAC(CONCATENATE("31/12/",YEAR(G9)),IF( YEARFRAC(H9,CONCATENATE("31/12/",YEAR(H9)),1)>0.502, CONCATENATE("31/12/",YEAR(H9)-1), CONCATENATE("31/12/",YEAR(H9)) ),1),0) )) | G9: {=IF(ISBLANK(N9)," ",_xlfn.XLOOKUP(D9,#REF!,#REF!))} | H9: =O9 -> 0 | I9: {=IF(ISBLANK(K9)," ",_xlfn.XLOOKUP(D9,#REF!,#REF!))} | J9: {=IF(ISBLANK(N9)," ",_xlfn.XLOOKUP(F9,Edades!$A$2:$A$101,IF(I9="F",Edades!$B$2:$B$101,Edades!$C$2:$C$101)))}
B10: De https://speedskatingresults.com/ | C10: =#REF! -> #REF! | D10: =#REF! -> #REF! | E10: =CONCATENATE("https://speedskatingresults.com/api/json/skater_competitions?skater=",D10,"&season=",$B$6) -> #REF! | F10: =IF(ISBLANK(N10)," ",IF( YEARFRAC(G10,CONCATENATE("31/12/",YEAR(G10)),1)>0.502, ROUND(YEARFRAC(CONCATENATE("31/12/",YEAR(G10)-1),IF( YEARFRAC(H10,CONCATENATE("31/12/",YEAR(H10)),1)>0.502, CONCATENATE("31/12/",YEAR(H10)-1), CONCATENATE("31/12/",YEAR(H10)) ),1),0), ROUND(YEARFRAC(CONCATENATE("31/12/",YEAR(G10)),IF( YEARFRAC(H10,CONCATENATE("31/12/",YEAR(H10)),1)>0.502, CONCATENATE("31/12/",YEAR(H10)-1), CONCATENATE("31/12/",YEAR(H10)) ),1),0) )) | G10: {=IF(ISBLANK(N10)," ",_xlfn.XLOOKUP(D10,#REF!,#REF!))} | H10: =O10 -> 0 | I10: {=IF(ISBLANK(K10)," ",_xlfn.XLOOKUP(D10,#REF!,#REF!))} | J10: {=IF(ISBLANK(N10)," ",_xlfn.XLOOKUP(F10,Edades!$A$2:$A$101,IF(I10="F",Edades!$B$2:$B$101,Edades!$C$2:$C$101)))}
C11: =#REF! -> #REF! | D11: =#REF! -> #REF! | E11: =CONCATENATE("https://speedskatingresults.com/api/json/skater_competitions?skater=",D11,"&season=",$B$6) -> #REF! | F11: =IF(ISBLANK(N11)," ",IF( YEARFRAC(G11,CONCATENATE("31/12/",YEAR(G11)),1)>0.502, ROUND(YEARFRAC(CONCATENATE("31/12/",YEAR(G11)-1),IF( YEARFRAC(H11,CONCATENATE("31/12/",YEAR(H11)),1)>0.502, CONCATENATE("31/12/",YEAR(H11)-1), CONCATENATE("31/12/",YEAR(H11)) ),1),0), ROUND(YEARFRAC(CONCATENATE("31/12/",YEAR(G11)),IF( YEARFRAC(H11,CONCATENATE("31/12/",YEAR(H11)),1)>0.502, CONCATENATE("31/12/",YEAR(H11)-1), CONCATENATE("31/12/",YEAR(H11)) ),1),0) )) | G11: {=IF(ISBLANK(N11)," ",_xlfn.XLOOKUP(D11,#REF!,#REF!))} | H11: =O11 -> 0 | I11: {=IF(ISBLANK(K11)," ",_xlfn.XLOOKUP(D11,#REF!,#REF!))} | J11: {=IF(ISBLANK(N11)," ",_xlfn.XLOOKUP(F11,Edades!$A$2:$A$101,IF(I11="F",Edades!$B$2:$B$101,Edades!$C$2:$C$101)))}
C12: =#REF! -> #REF! | D12: =#REF! -> #REF! | E12: =CONCATENATE("https://speedskatingresults.com/api/json/skater_competitions?skater=",D12,"&season=",$B$6) -> #REF! | F12: =IF(ISBLANK(N12)," ",IF( YEARFRAC(G12,CONCATENATE("31/12/",YEAR(G12)),1)>0.502, ROUND(YEARFRAC(CONCATENATE("31/12/",YEAR(G12)-1),IF( YEARFRAC(H12,CONCATENATE("31/12/",YEAR(H12)),1)>0.502, CONCATENATE("31/12/",YEAR(H12)-1), CONCATENATE("31/12/",YEAR(H12)) ),1),0), ROUND(YEARFRAC(CONCATENATE("31/12/",YEAR(G12)),IF( YEARFRAC(H12,CONCATENATE("31/12/",YEAR(H12)),1)>0.502, CONCATENATE("31/12/",YEAR(H12)-1), CONCATENATE("31/12/",YEAR(H12)) ),1),0) )) -> #NAME? | G12: {=IF(ISBLANK(N12)," ",_xlfn.XLOOKUP(D12,#REF!,#REF!))} -> #NAME? | H12: =O12 -> 2026-01-23 | I12: {=IF(ISBLANK(K12)," ",_xlfn.XLOOKUP(D12,#REF!,#REF!))} -> #NAME? | J12: {=IF(ISBLANK(N12)," ",_xlfn.XLOOKUP(F12,Edades!$A$2:$A$101,IF(I12="F",Edades!$B$2:$B$101,Edades!$C$2:$C$101)))} -> #NAME? | K12: =IFERROR(__xludf.DUMMYFUNCTION("index(query(importjson(E12)),2,)"),"83318") -> 83318 | L12: =IFERROR(__xludf.DUMMYFUNCTION("""COMPUTED_VALUE"""),"2025") -> 2025 | M12: =IFERROR(__xludf.DUMMYFUNCTION("""COMPUTED_VALUE"""),"31411") -> 31411 | N12: =IFERROR(__xludf.DUMMYFUNCTION("""COMPUTED_VALUE"""),"ISU Speed Skating World Cup #5") -> ISU Speed Skating World Cup #5 | O12: =IFERROR(__xludf.DUMMYFUNCTION("""COMPUTED_VALUE"""),"2026-01-23") -> 2026-01-23 | P12: =IFERROR(__xludf.DUMMYFUNCTION("""COMPUTED_VALUE"""),"2026-01-25") -> 2026-01-25 | Q12: =IFERROR(__xludf.DUMMYFUNCTION("""COMPUTED_VALUE"""),"Inzell (GER)") -> Inzell (GER) | R12: =IFERROR(__xludf.DUMMYFUNCTION("""COMPUTED_VALUE"""),"11") -> 11 | S12: =IFERROR(__xludf.DUMMYFUNCTION("""COMPUTED_VALUE"""),"http://speedskatingresults.com/index.php?p=2&e=31411&s=83318") -> http://speedskatingresults.com/index.php?p=2&e=31411&s=83318
C13: =#REF! -> #REF! | D13: =#REF! -> #REF! | E13: =CONCATENATE("https://speedskatingresults.com/api/json/skater_competitions?skater=",D13,"&season=",$B$6) -> #REF! | F13: =IF(ISBLANK(N13)," ",IF( YEARFRAC(G13,CONCATENATE("31/12/",YEAR(G13)),1)>0.502, ROUND(YEARFRAC(CONCATENATE("31/12/",YEAR(G13)-1),IF( YEARFRAC(H13,CONCATENATE("31/12/",YEAR(H13)),1)>0.502, CONCATENATE("31/12/",YEAR(H13)-1), CONCATENATE("31/12/",YEAR(H13)) ),1),0), ROUND(YEARFRAC(CONCATENATE("31/12/",YEAR(G13)),IF( YEARFRAC(H13,CONCATENATE("31/12/",YEAR(H13)),1)>0.502, CONCATENATE("31/12/",YEAR(H13)-1), CONCATENATE("31/12/",YEAR(H13)) ),1),0) )) | G13: {=IF(ISBLANK(N13)," ",_xlfn.XLOOKUP(D13,#REF!,#REF!))} | H13: =O13 -> 0 | I13: {=IF(ISBLANK(K13)," ",_xlfn.XLOOKUP(D13,#REF!,#REF!))} | J13: {=IF(ISBLANK(N13)," ",_xlfn.XLOOKUP(F13,Edades!$A$2:$A$101,IF(I13="F",Edades!$B$2:$B$101,Edades!$C$2:$C$101)))}
C14: =#REF! -> #REF! | D14: =#REF! -> #REF! | E14: =CONCATENATE("https://speedskatingresults.com/api/json/skater_competitions?skater=",D14,"&season=",$B$6) -> #REF! | F14: =IF(ISBLANK(N14)," ",IF( YEARFRAC(G14,CONCATENATE("31/12/",YEAR(G14)),1)>0.502, ROUND(YEARFRAC(CONCATENATE("31/12/",YEAR(G14)-1),IF( YEARFRAC(H14,CONCATENATE("31/12/",YEAR(H14)),1)>0.502, CONCATENATE("31/12/",YEAR(H14)-1), CONCATENATE("31/12/",YEAR(H14)) ),1),0), ROUND(YEARFRAC(CONCATENATE("31/12/",YEAR(G14)),IF( YEARFRAC(H14,CONCATENATE("31/12/",YEAR(H14)),1)>0.502, CONCATENATE("31/12/",YEAR(H14)-1), CONCATENATE("31/12/",YEAR(H14)) ),1),0) )) | G14: {=IF(ISBLANK(N14)," ",_xlfn.XLOOKUP(D14,#REF!,#REF!))} | H14: =O14 -> 0 | I14: {=IF(ISBLANK(K14)," ",_xlfn.XLOOKUP(D14,#REF!,#REF!))} | J14: {=IF(ISBLANK(N14)," ",_xlfn.XLOOKUP(F14,Edades!$A$2:$A$101,IF(I14="F",Edades!$B$2:$B$101,Edades!$C$2:$C$101)))}
C15: =#REF! -> #REF! | D15: =#REF! -> #REF! | E15: =CONCATENATE("https://speedskatingresults.com/api/json/skater_competitions?skater=",D15,"&season=",$B$6) -> #REF! | F15: =IF(ISBLANK(N15)," ",IF( YEARFRAC(G15,CONCATENATE("31/12/",YEAR(G15)),1)>0.502, ROUND(YEARFRAC(CONCATENATE("31/12/",YEAR(G15)-1),IF( YEARFRAC(H15,CONCATENATE("31/12/",YEAR(H15)),1)>0.502, CONCATENATE("31/12/",YEAR(H15)-1), CONCATENATE("31/12/",YEAR(H15)) ),1),0), ROUND(YEARFRAC(CONCATENATE("31/12/",YEAR(G15)),IF( YEARFRAC(H15,CONCATENATE("31/12/",YEAR(H15)),1)>0.502, CONCATENATE("31/12/",YEAR(H15)-1), CONCATENATE("31/12/",YEAR(H15)) ),1),0) )) | G15: {=IF(ISBLANK(N15)," ",_xlfn.XLOOKUP(D15,#REF!,#REF!))} | H15: =O15 -> 0 | I15: {=IF(ISBLANK(K15)," ",_xlfn.XLOOKUP(D15,#REF!,#REF!))} | J15: {=IF(ISBLANK(N15)," ",_xlfn.XLOOKUP(F15,Edades!$A$2:$A$101,IF(I15="F",Edades!$B$2:$B$101,Edades!$C$2:$C$101)))}
C16: =#REF! -> #REF! | D16: =#REF! -> #REF! | E16: =CONCATENATE("https://speedskatingresults.com/api/json/skater_competitions?skater=",D16,"&season=",$B$6) -> #REF! | F16: =IF(ISBLANK(N16)," ",IF( YEARFRAC(G16,CONCATENATE("31/12/",YEAR(G16)),1)>0.502, ROUND(YEARFRAC(CONCATENATE("31/12/",YEAR(G16)-1),IF( YEARFRAC(H16,CONCATENATE("31/12/",YEAR(H16)),1)>0.502, CONCATENATE("31/12/",YEAR(H16)-1), CONCATENATE("31/12/",YEAR(H16)) ),1),0), ROUND(YEARFRAC(CONCATENATE("31/12/",YEAR(G16)),IF( YEARFRAC(H16,CONCATENATE("31/12/",YEAR(H16)),1)>0.502, CONCATENATE("31/12/",YEAR(H16)-1), CONCATENATE("31/12/",YEAR(H16)) ),1),0) )) -> #NAME? | G16: {=IF(ISBLANK(N16)," ",_xlfn.XLOOKUP(D16,#REF!,#REF!))} -> #NAME? | H16: =O16 -> 2025-10-24 | I16: {=IF(ISBLANK(K16)," ",_xlfn.XLOOKUP(D16,#REF!,#REF!))} -> #NAME? | J16: {=IF(ISBLANK(N16)," ",_xlfn.XLOOKUP(F16,Edades!$A$2:$A$101,IF(I16="F",Edades!$B$2:$B$101,Edades!$C$2:$C$101)))} -> #NAME? | K16: =IFERROR(__xludf.DUMMYFUNCTION("index(query(importjson(E16)),2,)"),"120619") -> 120619 | L16: =IFERROR(__xludf.DUMMYFUNCTION("""COMPUTED_VALUE"""),"2025") -> 2025 | M16: =IFERROR(__xludf.DUMMYFUNCTION("""COMPUTED_VALUE"""),"30591") -> 30591 | N16: =IFERROR(__xludf.DUMMYFUNCTION("""COMPUTED_VALUE"""),"International Race") -> International Race | O16: =IFERROR(__xludf.DUMMYFUNCTION("""COMPUTED_VALUE"""),"2025-10-24") -> 2025-10-24 | P16: =IFERROR(__xludf.DUMMYFUNCTION("""COMPUTED_VALUE"""),"2025-10-26") -> 2025-10-26 | Q16: =IFERROR(__xludf.DUMMYFUNCTION("""COMPUTED_VALUE"""),"Inzell (GER)") -> Inzell (GER) | R16: =IFERROR(__xludf.DUMMYFUNCTION("""COMPUTED_VALUE"""),"11") -> 11 | S16: =IFERROR(__xludf.DUMMYFUNCTION("""COMPUTED_VALUE"""),"http://speedskatingresults.com/index.php?p=2&e=30591&s=120619") -> http://speedskatingresults.com/index.php?p=2&e=30591&s=120619
C17: =#REF! -> #REF! | D17: =#REF! -> #REF! | E17: =CONCATENATE("https://speedskatingresults.com/api/json/skater_competitions?skater=",D17,"&season=",$B$6) -> #REF! | F17: =IF(ISBLANK(N17)," ",IF( YEARFRAC(G17,CONCATENATE("31/12/",YEAR(G17)),1)>0.502, ROUND(YEARFRAC(CONCATENATE("31/12/",YEAR(G17)-1),IF( YEARFRAC(H17,CONCATENATE("31/12/",YEAR(H17)),1)>0.502, CONCATENATE("31/12/",YEAR(H17)-1), CONCATENATE("31/12/",YEAR(H17)) ),1),0), ROUND(YEARFRAC(CONCATENATE("31/12/",YEAR(G17)),IF( YEARFRAC(H17,CONCATENATE("31/12/",YEAR(H17)),1)>0.502, CONCATENATE("31/12/",YEAR(H17)-1), CONCATENATE("31/12/",YEAR(H17)) ),1),0) )) | G17: {=IF(ISBLANK(N17)," ",_xlfn.XLOOKUP(D17,#REF!,#REF!))} | H17: =O17 -> 0 | I17: {=IF(ISBLANK(K17)," ",_xlfn.XLOOKUP(D17,#REF!,#REF!))} | J17: {=IF(ISBLANK(N17)," ",_xlfn.XLOOKUP(F17,Edades!$A$2:$A$101,IF(I17="F",Edades!$B$2:$B$101,Edades!$C$2:$C$101)))}
C18: =#REF! -> #REF! | D18: =#REF! -> #REF! | E18: =CONCATENATE("https://speedskatingresults.com/api/json/skater_competitions?skater=",D18,"&season=",$B$6) -> #REF! | F18: =IF(ISBLANK(N18)," ",IF( YEARFRAC(G18,CONCATENATE("31/12/",YEAR(G18)),1)>0.502, ROUND(YEARFRAC(CONCATENATE("31/12/",YEAR(G18)-1),IF( YEARFRAC(H18,CONCATENATE("31/12/",YEAR(H18)),1)>0.502, CONCATENATE("31/12/",YEAR(H18)-1), CONCATENATE("31/12/",YEAR(H18)) ),1),0), ROUND(YEARFRAC(CONCATENATE("31/12/",YEAR(G18)),IF( YEARFRAC(H18,CONCATENATE("31/12/",YEAR(H18)),1)>0.502, CONCATENATE("31/12/",YEAR(H18)-1), CONCATENATE("31/12/",YEAR(H18)) ),1),0) )) | G18: {=IF(ISBLANK(N18)," ",_xlfn.XLOOKUP(D18,#REF!,#REF!))} | H18: =O18 -> 0 | I18: {=IF(ISBLANK(K18)," ",_xlfn.XLOOKUP(D18,#REF!,#REF!))} | J18: {=IF(ISBLANK(N18)," ",_xlfn.XLOOKUP(F18,Edades!$A$2:$A$101,IF(I18="F",Edades!$B$2:$B$101,Edades!$C$2:$C$101)))}
C19: =#REF! -> #REF! | D19: =#REF! -> #REF! | E19: =CONCATENATE("https://speedskatingresults.com/api/json/skater_competitions?skater=",D19,"&season=",$B$6) -> #REF! | F19: =IF(ISBLANK(N19)," ",IF( YEARFRAC(G19,CONCATENATE("31/12/",YEAR(G19)),1)>0.502, ROUND(YEARFRAC(CONCATENATE("31/12/",YEAR(G19)-1),IF( YEARFRAC(H19,CONCATENATE("31/12/",YEAR(H19)),1)>0.502, CONCATENATE("31/12/",YEAR(H19)-1), CONCATENATE("31/12/",YEAR(H19)) ),1),0), ROUND(YEARFRAC(CONCATENATE("31/12/",YEAR(G19)),IF( YEARFRAC(H19,CONCATENATE("31/12/",YEAR(H19)),1)>0.502, CONCATENATE("31/12/",YEAR(H19)-1), CONCATENATE("31/12/",YEAR(H19)) ),1),0) )) -> #NAME? | G19: {=IF(ISBLANK(N19)," ",_xlfn.XLOOKUP(D19,#REF!,#REF!))} -> #NAME? | H19: =O19 -> 2026-02-21 | I19: {=IF(ISBLANK(K19)," ",_xlfn.XLOOKUP(D19,#REF!,#REF!))} -> #NAME? | J19: {=IF(ISBLANK(N19)," ",_xlfn.XLOOKUP(F19,Edades!$A$2:$A$101,IF(I19="F",Edades!$B$2:$B$101,Edades!$C$2:$C$101)))} -> #NAME? | K19: =IFERROR(__xludf.DUMMYFUNCTION("index(query(importjson(E19)),2,)"),"114671") -> 114671 | L19: =IFERROR(__xludf.DUMMYFUNCTION("""COMPUTED_VALUE"""),"2025") -> 2025 | M19: =IFERROR(__xludf.DUMMYFUNCTION("""COMPUTED_VALUE"""),"31719") -> 31719 | N19: =IFERROR(__xludf.DUMMYFUNCTION("""COMPUTED_VALUE"""),"ISU Speed Skating Junior World Cup #3") -> ISU Speed Skating Junior World Cup #3 | O19: =IFERROR(__xludf.DUMMYFUNCTION("""COMPUTED_VALUE"""),"2026-02-21") -> 2026-02-21 | P19: =IFERROR(__xludf.DUMMYFUNCTION("""COMPUTED_VALUE"""),"2026-02-22") -> 2026-02-22 | Q19: =IFERROR(__xludf.DUMMYFUNCTION("""COMPUTED_VALUE"""),"Inzell (GER)") -> Inzell (GER) | R19: =IFERROR(__xludf.DUMMYFUNCTION("""COMPUTED_VALUE"""),"11") -> 11 | S19: =IFERROR(__xludf.DUMMYFUNCTION("""COMPUTED_VALUE"""),"http://speedskatingresults.com/index.php?p=2&e=31719&s=114671") -> http://speedskatingresults.com/index.php?p=2&e=31719&s=114671
C20: =#REF! -> #REF! | D20: =#REF! -> #REF! | E20: =CONCATENATE("https://speedskatingresults.com/api/json/skater_competitions?skater=",D20,"&season=",$B$6) -> #REF! | F20: =IF(ISBLANK(N20)," ",IF( YEARFRAC(G20,CONCATENATE("31/12/",YEAR(G20)),1)>0.502, ROUND(YEARFRAC(CONCATENATE("31/12/",YEAR(G20)-1),IF( YEARFRAC(H20,CONCATENATE("31/12/",YEAR(H20)),1)>0.502, CONCATENATE("31/12/",YEAR(H20)-1), CONCATENATE("31/12/",YEAR(H20)) ),1),0), ROUND(YEARFRAC(CONCATENATE("31/12/",YEAR(G20)),IF( YEARFRAC(H20,CONCATENATE("31/12/",YEAR(H20)),1)>0.502, CONCATENATE("31/12/",YEAR(H20)-1), CONCATENATE("31/12/",YEAR(H20)) ),1),0) )) -> #NAME? | G20: {=IF(ISBLANK(N20)," ",_xlfn.XLOOKUP(D20,#REF!,#REF!))} -> #NAME? | H20: =O20 -> 2025-10-24 | I20: {=IF(ISBLANK(K20)," ",_xlfn.XLOOKUP(D20,#REF!,#REF!))} -> #NAME? | J20: {=IF(ISBLANK(N20)," ",_xlfn.XLOOKUP(F20,Edades!$A$2:$A$101,IF(I20="F",Edades!$B$2:$B$101,Edades!$C$2:$C$101)))} -> #NAME? | K20: =IFERROR(__xludf.DUMMYFUNCTION("index(query(importjson(E20)),2,)"),"115280") -> 115280 | L20: =IFERROR(__xludf.DUMMYFUNCTION("""COMPUTED_VALUE"""),"2025") -> 2025 | M20: =IFERROR(__xludf.DUMMYFUNCTION("""COMPUTED_VALUE"""),"30591") -> 30591 | N20: =IFERROR(__xludf.DUMMYFUNCTION("""COMPUTED_VALUE"""),"International Race") -> International Race | O20: =IFERROR(__xludf.DUMMYFUNCTION("""COMPUTED_VALUE"""),"2025-10-24") -> 2025-10-24 | P20: =IFERROR(__xludf.DUMMYFUNCTION("""COMPUTED_VALUE"""),"2025-10-26") -> 2025-10-26 | Q20: =IFERROR(__xludf.DUMMYFUNCTION("""COMPUTED_VALUE"""),"Inzell (GER)") -> Inzell (GER) | R20: =IFERROR(__xludf.DUMMYFUNCTION("""COMPUTED_VALUE"""),"11") -> 11 | S20: =IFERROR(__xludf.DUMMYFUNCTION("""COMPUTED_VALUE"""),"http://speedskatingresults.com/index.php?p=2&e=30591&s=115280") -> http://speedskatingresults.com/index.php?p=2&e=30591&s=115280
C21: =#REF! -> #REF! | D21: =#REF! -> #REF! | E21: =CONCATENATE("https://speedskatingresults.com/api/json/skater_competitions?skater=",D21,"&season=",$B$6) -> #REF! | F21: =IF(ISBLANK(N21)," ",IF( YEARFRAC(G21,CONCATENATE("31/12/",YEAR(G21)),1)>0.502, ROUND(YEARFRAC(CONCATENATE("31/12/",YEAR(G21)-1),IF( YEARFRAC(H21,CONCATENATE("31/12/",YEAR(H21)),1)>0.502, CONCATENATE("31/12/",YEAR(H21)-1), CONCATENATE("31/12/",YEAR(H21)) ),1),0), ROUND(YEARFRAC(CONCATENATE("31/12/",YEAR(G21)),IF( YEARFRAC(H21,CONCATENATE("31/12/",YEAR(H21)),1)>0.502, CONCATENATE("31/12/",YEAR(H21)-1), CONCATENATE("31/12/",YEAR(H21)) ),1),0) )) | G21: {=IF(ISBLANK(N21)," ",_xlfn.XLOOKUP(D21,#REF!,#REF!))} | H21: =O21 -> 0 | I21: {=IF(ISBLANK(K21)," ",_xlfn.XLOOKUP(D21,#REF!,#REF!))} | J21: {=IF(ISBLANK(N21)," ",_xlfn.XLOOKUP(F21,Edades!$A$2:$A$101,IF(I21="F",Edades!$B$2:$B$101,Edades!$C$2:$C$101)))}
C22: =#REF! -> #REF! | D22: =#REF! -> #REF! | E22: =CONCATENATE("https://speedskatingresults.com/api/json/skater_competitions?skater=",D22,"&season=",$B$6) -> #REF! | F22: =IF(ISBLANK(N22)," ",IF( YEARFRAC(G22,CONCATENATE("31/12/",YEAR(G22)),1)>0.502, ROUND(YEARFRAC(CONCATENATE("31/12/",YEAR(G22)-1),IF( YEARFRAC(H22,CONCATENATE("31/12/",YEAR(H22)),1)>0.502, CONCATENATE("31/12/",YEAR(H22)-1), CONCATENATE("31/12/",YEAR(H22)) ),1),0), ROUND(YEARFRAC(CONCATENATE("31/12/",YEAR(G22)),IF( YEARFRAC(H22,CONCATENATE("31/12/",YEAR(H22)),1)>0.502, CONCATENATE("31/12/",YEAR(H22)-1), CONCATENATE("31/12/",YEAR(H22)) ),1),0) )) -> #NAME? | G22: {=IF(ISBLANK(N22)," ",_xlfn.XLOOKUP(D22,#REF!,#REF!))} -> #NAME? | H22: =O22 -> 2026-02-27 | I22: {=IF(ISBLANK(K22)," ",_xlfn.XLOOKUP(D22,#REF!,#REF!))} -> #NAME? | J22: {=IF(ISBLANK(N22)," ",_xlfn.XLOOKUP(F22,Edades!$A$2:$A$101,IF(I22="F",Edades!$B$2:$B$101,Edades!$C$2:$C$101)))} -> #NAME? | K22: =IFERROR(__xludf.DUMMYFUNCTION("index(query(importjson(E22)),2,)"),"86207") -> 86207 | L22: =IFERROR(__xludf.DUMMYFUNCTION("""COMPUTED_VALUE"""),"2025") -> 2025 | M22: =IFERROR(__xludf.DUMMYFUNCTION("""COMPUTED_VALUE"""),"31773") -> 31773 | N22: =IFERROR(__xludf.DUMMYFUNCTION("""COMPUTED_VALUE"""),"ISU Junior World Championships 2026") -> ISU Junior World Championships 2026 | O22: =IFERROR(__xludf.DUMMYFUNCTION("""COMPUTED_VALUE"""),"2026-02-27") -> 2026-02-27 | P22: =IFERROR(__xludf.DUMMYFUNCTION("""COMPUTED_VALUE"""),"2026-03-01") -> 2026-03-01 | Q22: =IFERROR(__xludf.DUMMYFUNCTION("""COMPUTED_VALUE"""),"Inzell (GER)") -> Inzell (GER) | R22: =IFERROR(__xludf.DUMMYFUNCTION("""COMPUTED_VALUE"""),"11") -> 11 | S22: =IFERROR(__xludf.DUMMYFUNCTION("""COMPUTED_VALUE"""),"http://speedskatingresults.com/index.php?p=2&e=31773&s=86207") -> http://speedskatingresults.com/index.php?p=2&e=31773&s=86207
C23: =#REF! -> #REF! | D23: =#REF! -> #REF! | E23: =CONCATENATE("https://speedskatingresults.com/api/json/skater_competitions?skater=",D23,"&season=",$B$6) -> #REF! | F23: =IF(ISBLANK(N23)," ",IF( YEARFRAC(G23,CONCATENATE("31/12/",YEAR(G23)),1)>0.502, ROUND(YEARFRAC(CONCATENATE("31/12/",YEAR(G23)-1),IF( YEARFRAC(H23,CONCATENATE("31/12/",YEAR(H23)),1)>0.502, CONCATENATE("31/12/",YEAR(H23)-1), CONCATENATE("31/12/",YEAR(H23)) ),1),0), ROUND(YEARFRAC(CONCATENATE("31/12/",YEAR(G23)),IF( YEARFRAC(H23,CONCATENATE("31/12/",YEAR(H23)),1)>0.502, CONCATENATE("31/12/",YEAR(H23)-1), CONCATENATE("31/12/",YEAR(H23)) ),1),0) )) | G23: {=IF(ISBLANK(N23)," ",_xlfn.XLOOKUP(D23,#REF!,#REF!))} | H23: =O23 -> 0 | I23: {=IF(ISBLANK(K23)," ",_xlfn.XLOOKUP(D23,#REF!,#REF!))} | J23: {=IF(ISBLANK(N23)," ",_xlfn.XLOOKUP(F23,Edades!$A$2:$A$101,IF(I23="F",Edades!$B$2:$B$101,Edades!$C$2:$C$101)))}
C24: =#REF! -> #REF! | D24: =#REF! -> #REF! | E24: =CONCATENATE("https://speedskatingresults.com/api/json/skater_competitions?skater=",D24,"&season=",$B$6) -> #REF! | F24: =IF(ISBLANK(N24)," ",IF( YEARFRAC(G24,CONCATENATE("31/12/",YEAR(G24)),1)>0.502, ROUND(YEARFRAC(CONCATENATE("31/12/",YEAR(G24)-1),IF( YEARFRAC(H24,CONCATENATE("31/12/",YEAR(H24)),1)>0.502, CONCATENATE("31/12/",YEAR(H24)-1), CONCATENATE("31/12/",YEAR(H24)) ),1),0), ROUND(YEARFRAC(CONCATENATE("31/12/",YEAR(G24)),IF( YEARFRAC(H24,CONCATENATE("31/12/",YEAR(H24)),1)>0.502, CONCATENATE("31/12/",YEAR(H24)-1), CONCATENATE("31/12/",YEAR(H24)) ),1),0) )) -> #NAME? | G24: {=IF(ISBLANK(N24)," ",_xlfn.XLOOKUP(D24,#REF!,#REF!))} -> #NAME? | H24: =O24 -> 2025-10-24 | I24: {=IF(ISBLANK(K24)," ",_xlfn.XLOOKUP(D24,#REF!,#REF!))} -> #NAME? | J24: {=IF(ISBLANK(N24)," ",_xlfn.XLOOKUP(F24,Edades!$A$2:$A$101,IF(I24="F",Edades!$B$2:$B$101,Edades!$C$2:$C$101)))} -> #NAME? | K24: =IFERROR(__xludf.DUMMYFUNCTION("index(query(importjson(E24)),2,)"),"114230") -> 114230 | L24: =IFERROR(__xludf.DUMMYFUNCTION("""COMPUTED_VALUE"""),"2025") -> 2025 | M24: =IFERROR(__xludf.DUMMYFUNCTION("""COMPUTED_VALUE"""),"30591") -> 30591 | N24: =IFERROR(__xludf.DUMMYFUNCTION("""COMPUTED_VALUE"""),"International Race") -> International Race | O24: =IFERROR(__xludf.DUMMYFUNCTION("""COMPUTED_VALUE"""),"2025-10-24") -> 2025-10-24 | P24: =IFERROR(__xludf.DUMMYFUNCTION("""COMPUTED_VALUE"""),"2025-10-26") -> 2025-10-26 | Q24: =IFERROR(__xludf.DUMMYFUNCTION("""COMPUTED_VALUE"""),"Inzell (GER)") -> Inzell (GER) | R24: =IFERROR(__xludf.DUMMYFUNCTION("""COMPUTED_VALUE"""),"11") -> 11 | S24: =IFERROR(__xludf.DUMMYFUNCTION("""COMPUTED_VALUE"""),"http://speedskatingresults.com/index.php?p=2&e=30591&s=114230") -> http://speedskatingresults.com/index.php?p=2&e=30591&s=114230
C25: =#REF! -> #REF! | D25: =#REF! -> #REF! | E25: =CONCATENATE("https://speedskatingresults.com/api/json/skater_competitions?skater=",D25,"&season=",$B$6) -> #REF! | F25: =IF(ISBLANK(N25)," ",IF( YEARFRAC(G25,CONCATENATE("31/12/",YEAR(G25)),1)>0.502, ROUND(YEARFRAC(CONCATENATE("31/12/",YEAR(G25)-1),IF( YEARFRAC(H25,CONCATENATE("31/12/",YEAR(H25)),1)>0.502, CONCATENATE("31/12/",YEAR(H25)-1), CONCATENATE("31/12/",YEAR(H25)) ),1),0), ROUND(YEARFRAC(CONCATENATE("31/12/",YEAR(G25)),IF( YEARFRAC(H25,CONCATENATE("31/12/",YEAR(H25)),1)>0.502, CONCATENATE("31/12/",YEAR(H25)-1), CONCATENATE("31/12/",YEAR(H25)) ),1),0) )) | G25: {=IF(ISBLANK(N25)," ",_xlfn.XLOOKUP(D25,#REF!,#REF!))} | H25: =O25 -> 0 | I25: {=IF(ISBLANK(K25)," ",_xlfn.XLOOKUP(D25,#REF!,#REF!))} | J25: {=IF(ISBLANK(N25)," ",_xlfn.XLOOKUP(F25,Edades!$A$2:$A$101,IF(I25="F",Edades!$B$2:$B$101,Edades!$C$2:$C$101)))}
C26: =#REF! -> #REF! | D26: =#REF! -> #REF! | E26: =CONCATENATE("https://speedskatingresults.com/api/json/skater_competitions?skater=",D26,"&season=",$B$6) -> #REF! | F26: =IF(ISBLANK(N26)," ",IF( YEARFRAC(G26,CONCATENATE("31/12/",YEAR(G26)),1)>0.502, ROUND(YEARFRAC(CONCATENATE("31/12/",YEAR(G26)-1),IF( YEARFRAC(H26,CONCATENATE("31/12/",YEAR(H26)),1)>0.502, CONCATENATE("31/12/",YEAR(H26)-1), CONCATENATE("31/12/",YEAR(H26)) ),1),0), ROUND(YEARFRAC(CONCATENATE("31/12/",YEAR(G26)),IF( YEARFRAC(H26,CONCATENATE("31/12/",YEAR(H26)),1)>0.502, CONCATENATE("31/12/",YEAR(H26)-1), CONCATENATE("31/12/",YEAR(H26)) ),1),0) )) | G26: {=IF(ISBLANK(N26)," ",_xlfn.XLOOKUP(D26,#REF!,#REF!))} | H26: =O26 -> 0 | I26: {=IF(ISBLANK(K26)," ",_xlfn.XLOOKUP(D26,#REF!,#REF!))} | J26: {=IF(ISBLANK(N26)," ",_xlfn.XLOOKUP(F26,Edades!$A$2:$A$101,IF(I26="F",Edades!$B$2:$B$101,Edades!$C$2:$C$101)))}
C27: =#REF! -> #REF! | D27: =#REF! -> #REF! | E27: =CONCATENATE("https://speedskatingresults.com/api/json/skater_competitions?skater=",D27,"&season=",$B$6) -> #REF! | F27: =IF(ISBLANK(N27)," ",IF( YEARFRAC(G27,CONCATENATE("31/12/",YEAR(G27)),1)>0.502, ROUND(YEARFRAC(CONCATENATE("31/12/",YEAR(G27)-1),IF( YEARFRAC(H27,CONCATENATE("31/12/",YEAR(H27)),1)>0.502, CONCATENATE("31/12/",YEAR(H27)-1), CONCATENATE("31/12/",YEAR(H27)) ),1),0), ROUND(YEARFRAC(CONCATENATE("31/12/",YEAR(G27)),IF( YEARFRAC(H27,CONCATENATE("31/12/",YEAR(H27)),1)>0.502, CONCATENATE("31/12/",YEAR(H27)-1), CONCATENATE("31/12/",YEAR(H27)) ),1),0) )) -> #NAME? | G27: {=IF(ISBLANK(N27)," ",_xlfn.XLOOKUP(D27,#REF!,#REF!))} -> #NAME? | H27: =O27 -> 2026-02-21 | I27: {=IF(ISBLANK(K27)," ",_xlfn.XLOOKUP(D27,#REF!,#REF!))} -> #NAME? | J27: {=IF(ISBLANK(N27)," ",_xlfn.XLOOKUP(F27,Edades!$A$2:$A$101,IF(I27="F",Edades!$B$2:$B$101,Edades!$C$2:$C$101)))} -> #NAME? | K27: =IFERROR(__xludf.DUMMYFUNCTION("index(query(importjson(E27)),2,)"),"106984") -> 106984 | L27: =IFERROR(__xludf.DUMMYFUNCTION("""COMPUTED_VALUE"""),"2025") -> 2025 | M27: =IFERROR(__xludf.DUMMYFUNCTION("""COMPUTED_VALUE"""),"31719") -> 31719 | N27: =IFERROR(__xludf.DUMMYFUNCTION("""COMPUTED_VALUE"""),"ISU Speed Skating Junior World Cup #3") -> ISU Speed Skating Junior World Cup #3 | O27: =IFERROR(__xludf.DUMMYFUNCTION("""COMPUTED_VALUE"""),"2026-02-21") -> 2026-02-21 | P27: =IFERROR(__xludf.DUMMYFUNCTION("""COMPUTED_VALUE"""),"2026-02-22") -> 2026-02-22 | Q27: =IFERROR(__xludf.DUMMYFUNCTION("""COMPUTED_VALUE"""),"Inzell (GER)") -> Inzell (GER) | R27: =IFERROR(__xludf.DUMMYFUNCTION("""COMPUTED_VALUE"""),"11") -> 11 | S27: =IFERROR(__xludf.DUMMYFUNCTION("""COMPUTED_VALUE"""),"http://speedskatingresults.com/index.php?p=2&e=31719&s=106984") -> http://speedskatingresults.com/index.php?p=2&e=31719&s=106984
C28: =#REF! -> #REF! | D28: =#REF! -> #REF! | E28: =CONCATENATE("https://speedskatingresults.com/api/json/skater_competitions?skater=",D28,"&season=",$B$6) -> #REF! | F28: =IF(ISBLANK(N28)," ",IF( YEARFRAC(G28,CONCATENATE("31/12/",YEAR(G28)),1)>0.502, ROUND(YEARFRAC(CONCATENATE("31/12/",YEAR(G28)-1),IF( YEARFRAC(H28,CONCATENATE("31/12/",YEAR(H28)),1)>0.502, CONCATENATE("31/12/",YEAR(H28)-1), CONCATENATE("31/12/",YEAR(H28)) ),1),0), ROUND(YEARFRAC(CONCATENATE("31/12/",YEAR(G28)),IF( YEARFRAC(H28,CONCATENATE("31/12/",YEAR(H28)),1)>0.502, CONCATENATE("31/12/",YEAR(H28)-1), CONCATENATE("31/12/",YEAR(H28)) ),1),0) )) | G28: {=IF(ISBLANK(N28)," ",_xlfn.XLOOKUP(D28,#REF!,#REF!))} | H28: =O28 -> 0 | I28: {=IF(ISBLANK(K28)," ",_xlfn.XLOOKUP(D28,#REF!,#REF!))} | J28: {=IF(ISBLANK(N28)," ",_xlfn.XLOOKUP(F28,Edades!$A$2:$A$101,IF(I28="F",Edades!$B$2:$B$101,Edades!$C$2:$C$101)))}
C29: =#REF! -> #REF! | D29: =#REF! -> #REF! | E29: =CONCATENATE("https://speedskatingresults.com/api/json/skater_competitions?skater=",D29,"&season=",$B$6) -> #REF! | F29: =IF(ISBLANK(N29)," ",IF( YEARFRAC(G29,CONCATENATE("31/12/",YEAR(G29)),1)>0.502, ROUND(YEARFRAC(CONCATENATE("31/12/",YEAR(G29)-1),IF( YEARFRAC(H29,CONCATENATE("31/12/",YEAR(H29)),1)>0.502, CONCATENATE("31/12/",YEAR(H29)-1), CONCATENATE("31/12/",YEAR(H29)) ),1),0), ROUND(YEARFRAC(CONCATENATE("31/12/",YEAR(G29)),IF( YEARFRAC(H29,CONCATENATE("31/12/",YEAR(H29)),1)>0.502, CONCATENATE("31/12/",YEAR(H29)-1), CONCATENATE("31/12/",YEAR(H29)) ),1),0) )) -> #NAME? | G29: {=IF(ISBLANK(N29)," ",_xlfn.XLOOKUP(D29,#REF!,#REF!))} -> #NAME? | H29: =O29 -> 2025-10-24 | I29: {=IF(ISBLANK(K29)," ",_xlfn.XLOOKUP(D29,#REF!,#REF!))} -> #NAME? | J29: {=IF(ISBLANK(N29)," ",_xlfn.XLOOKUP(F29,Edades!$A$2:$A$101,IF(I29="F",Edades!$B$2:$B$101,Edades!$C$2:$C$101)))} -> #NAME? | K29: =IFERROR(__xludf.DUMMYFUNCTION("index(query(importjson(E29)),2,)"),"114229") -> 114229 | L29: =IFERROR(__xludf.DUMMYFUNCTION("""COMPUTED_VALUE"""),"2025") -> 2025 | M29: =IFERROR(__xludf.DUMMYFUNCTION("""COMPUTED_VALUE"""),"30591") -> 30591 | N29: =IFERROR(__xludf.DUMMYFUNCTION("""COMPUTED_VALUE"""),"International Race") -> International Race | O29: =IFERROR(__xludf.DUMMYFUNCTION("""COMPUTED_VALUE"""),"2025-10-24") -> 2025-10-24 | P29: =IFERROR(__xludf.DUMMYFUNCTION("""COMPUTED_VALUE"""),"2025-10-26") -> 2025-10-26 | Q29: =IFERROR(__xludf.DUMMYFUNCTION("""COMPUTED_VALUE"""),"Inzell (GER)") -> Inzell (GER) | R29: =IFERROR(__xludf.DUMMYFUNCTION("""COMPUTED_VALUE"""),"11") -> 11 | S29: =IFERROR(__xludf.DUMMYFUNCTION("""COMPUTED_VALUE"""),"http://speedskatingresults.com/index.php?p=2&e=30591&s=114229") -> http://speedskatingresults.com/index.php?p=2&e=30591&s=114229
C30: =#REF! -> #REF! | D30: =#REF! -> #REF! | E30: =CONCATENATE("https://speedskatingresults.com/api/json/skater_competitions?skater=",D30,"&season=",$B$6) -> #REF! | F30: =IF(ISBLANK(N30)," ",IF( YEARFRAC(G30,CONCATENATE("31/12/",YEAR(G30)),1)>0.502, ROUND(YEARFRAC(CONCATENATE("31/12/",YEAR(G30)-1),IF( YEARFRAC(H30,CONCATENATE("31/12/",YEAR(H30)),1)>0.502, CONCATENATE("31/12/",YEAR(H30)-1), CONCATENATE("31/12/",YEAR(H30)) ),1),0), ROUND(YEARFRAC(CONCATENATE("31/12/",YEAR(G30)),IF( YEARFRAC(H30,CONCATENATE("31/12/",YEAR(H30)),1)>0.502, CONCATENATE("31/12/",YEAR(H30)-1), CONCATENATE("31/12/",YEAR(H30)) ),1),0) )) | G30: {=IF(ISBLANK(N30)," ",_xlfn.XLOOKUP(D30,#REF!,#REF!))} | H30: =O30 -> 0 | I30: {=IF(ISBLANK(K30)," ",_xlfn.XLOOKUP(D30,#REF!,#REF!))} | J30: {=IF(ISBLANK(N30)," ",_xlfn.XLOOKUP(F30,Edades!$A$2:$A$101,IF(I30="F",Edades!$B$2:$B$101,Edades!$C$2:$C$101)))}
C31: =#REF! -> #REF! | D31: =#REF! -> #REF! | E31: =CONCATENATE("https://speedskatingresults.com/api/json/skater_competitions?skater=",D31,"&season=",$B$6) -> #REF! | F31: =IF(ISBLANK(N31)," ",IF( YEARFRAC(G31,CONCATENATE("31/12/",YEAR(G31)),1)>0.502, ROUND(YEARFRAC(CONCATENATE("31/12/",YEAR(G31)-1),IF( YEARFRAC(H31,CONCATENATE("31/12/",YEAR(H31)),1)>0.502, CONCATENATE("31/12/",YEAR(H31)-1), CONCATENATE("31/12/",YEAR(H31)) ),1),0), ROUND(YEARFRAC(CONCATENATE("31/12/",YEAR(G31)),IF( YEARFRAC(H31,CONCATENATE("31/12/",YEAR(H31)),1)>0.502, CONCATENATE("31/12/",YEAR(H31)-1), CONCATENATE("31/12/",YEAR(H31)) ),1),0) )) -> #NAME? | G31: {=IF(ISBLANK(N31)," ",_xlfn.XLOOKUP(D31,#REF!,#REF!))} -> #NAME? | H31: =O31 -> 2025-10-24 | I31: {=IF(ISBLANK(K31)," ",_xlfn.XLOOKUP(D31,#REF!,#REF!))} -> #NAME? | J31: {=IF(ISBLANK(N31)," ",_xlfn.XLOOKUP(F31,Edades!$A$2:$A$101,IF(I31="F",Edades!$B$2:$B$101,Edades!$C$2:$C$101)))} -> #NAME? | K31: =IFERROR(__xludf.DUMMYFUNCTION("index(query(importjson(E31)),2,)"),"99863") -> 99863 | L31: =IFERROR(__xludf.DUMMYFUNCTION("""COMPUTED_VALUE"""),"2025") -> 2025 | M31: =IFERROR(__xludf.DUMMYFUNCTION("""COMPUTED_VALUE"""),"30591") -> 30591 | N31: =IFERROR(__xludf.DUMMYFUNCTION("""COMPUTED_VALUE"""),"International Race") -> International Race | O31: =IFERROR(__xludf.DUMMYFUNCTION("""COMPUTED_VALUE"""),"2025-10-24") -> 2025-10-24 | P31: =IFERROR(__xludf.DUMMYFUNCTION("""COMPUTED_VALUE"""),"2025-10-26") -> 2025-10-26 | Q31: =IFERROR(__xludf.DUMMYFUNCTION("""COMPUTED_VALUE"""),"Inzell (GER)") -> Inzell (GER) | R31: =IFERROR(__xludf.DUMMYFUNCTION("""COMPUTED_VALUE"""),"11") -> 11 | S31: =IFERROR(__xludf.DUMMYFUNCTION("""COMPUTED_VALUE"""),"http://speedskatingresults.com/index.php?p=2&e=30591&s=99863") -> http://speedskatingresults.com/index.php?p=2&e=30591&s=99863
C32: =#REF! -> #REF! | D32: =#REF! -> #REF! | E32: =CONCATENATE("https://speedskatingresults.com/api/json/skater_competitions?skater=",D32,"&season=",$B$6) -> #REF! | F32: =IF(ISBLANK(N32)," ",IF( YEARFRAC(G32,CONCATENATE("31/12/",YEAR(G32)),1)>0.502, ROUND(YEARFRAC(CONCATENATE("31/12/",YEAR(G32)-1),IF( YEARFRAC(H32,CONCATENATE("31/12/",YEAR(H32)),1)>0.502, CONCATENATE("31/12/",YEAR(H32)-1), CONCATENATE("31/12/",YEAR(H32)) ),1),0), ROUND(YEARFRAC(CONCATENATE("31/12/",YEAR(G32)),IF( YEARFRAC(H32,CONCATENATE("31/12/",YEAR(H32)),1)>0.502, CONCATENATE("31/12/",YEAR(H32)-1), CONCATENATE("31/12/",YEAR(H32)) ),1),0) )) | G32: {=IF(ISBLANK(N32)," ",_xlfn.XLOOKUP(D32,#REF!,#REF!))} | H32: =O32 -> 0 | I32: {=IF(ISBLANK(K32)," ",_xlfn.XLOOKUP(D32,#REF!,#REF!))} | J32: {=IF(ISBLANK(N32)," ",_xlfn.XLOOKUP(F32,Edades!$A$2:$A$101,IF(I32="F",Edades!$B$2:$B$101,Edades!$C$2:$C$101)))}
C33: =#REF! -> #REF! | D33: =#REF! -> #REF! | E33: =CONCATENATE("https://speedskatingresults.com/api/json/skater_competitions?skater=",D33,"&season=",$B$6) -> #REF! | F33: =IF(ISBLANK(N33)," ",IF( YEARFRAC(G33,CONCATENATE("31/12/",YEAR(G33)),1)>0.502, ROUND(YEARFRAC(CONCATENATE("31/12/",YEAR(G33)-1),IF( YEARFRAC(H33,CONCATENATE("31/12/",YEAR(H33)),1)>0.502, CONCATENATE("31/12/",YEAR(H33)-1), CONCATENATE("31/12/",YEAR(H33)) ),1),0), ROUND(YEARFRAC(CONCATENATE("31/12/",YEAR(G33)),IF( YEARFRAC(H33,CONCATENATE("31/12/",YEAR(H33)),1)>0.502, CONCATENATE("31/12/",YEAR(H33)-1), CONCATENATE("31/12/",YEAR(H33)) ),1),0) )) | G33: {=IF(ISBLANK(N33)," ",_xlfn.XLOOKUP(D33,#REF!,#REF!))} | H33: =O33 -> 0 | I33: {=IF(ISBLANK(K33)," ",_xlfn.XLOOKUP(D33,#REF!,#REF!))} | J33: {=IF(ISBLANK(N33)," ",_xlfn.XLOOKUP(F33,Edades!$A$2:$A$101,IF(I33="F",Edades!$B$2:$B$101,Edades!$C$2:$C$101)))}
C34: =#REF! -> #REF! | D34: =#REF! -> #REF! | E34: =CONCATENATE("https://speedskatingresults.com/api/json/skater_competitions?skater=",D34,"&season=",$B$6) -> #REF! | F34: =IF(ISBLANK(N34)," ",IF( YEARFRAC(G34,CONCATENATE("31/12/",YEAR(G34)),1)>0.502, ROUND(YEARFRAC(CONCATENATE("31/12/",YEAR(G34)-1),IF( YEARFRAC(H34,CONCATENATE("31/12/",YEAR(H34)),1)>0.502, CONCATENATE("31/12/",YEAR(H34)-1), CONCATENATE("31/12/",YEAR(H34)) ),1),0), ROUND(YEARFRAC(CONCATENATE("31/12/",YEAR(G34)),IF( YEARFRAC(H34,CONCATENATE("31/12/",YEAR(H34)),1)>0.502, CONCATENATE("31/12/",YEAR(H34)-1), CONCATENATE("31/12/",YEAR(H34)) ),1),0) )) | G34: {=IF(ISBLANK(N34)," ",_xlfn.XLOOKUP(D34,#REF!,#REF!))} | H34: =O34 -> 0 | I34: {=IF(ISBLANK(K34)," ",_xlfn.XLOOKUP(D34,#REF!,#REF!))} | J34: {=IF(ISBLANK(N34)," ",_xlfn.XLOOKUP(F34,Edades!$A$2:$A$101,IF(I34="F",Edades!$B$2:$B$101,Edades!$C$2:$C$101)))}
C35: =#REF! -> #REF! | D35: =#REF! -> #REF! | E35: =CONCATENATE("https://speedskatingresults.com/api/json/skater_competitions?skater=",D35,"&season=",$B$6) -> #REF! | F35: =IF(ISBLANK(N35)," ",IF( YEARFRAC(G35,CONCATENATE("31/12/",YEAR(G35)),1)>0.502, ROUND(YEARFRAC(CONCATENATE("31/12/",YEAR(G35)-1),IF( YEARFRAC(H35,CONCATENATE("31/12/",YEAR(H35)),1)>0.502, CONCATENATE("31/12/",YEAR(H35)-1), CONCATENATE("31/12/",YEAR(H35)) ),1),0), ROUND(YEARFRAC(CONCATENATE("31/12/",YEAR(G35)),IF( YEARFRAC(H35,CONCATENATE("31/12/",YEAR(H35)),1)>0.502, CONCATENATE("31/12/",YEAR(H35)-1), CONCATENATE("31/12/",YEAR(H35)) ),1),0) )) -> #NAME? | G35: {=IF(ISBLANK(N35)," ",_xlfn.XLOOKUP(D35,#REF!,#REF!))} -> #NAME? | H35: =O35 -> 2026-03-15 | I35: {=IF(ISBLANK(K35)," ",_xlfn.XLOOKUP(D35,#REF!,#REF!))} -> #NAME? | J35: {=IF(ISBLANK(N35)," ",_xlfn.XLOOKUP(F35,Edades!$A$2:$A$101,IF(I35="F",Edades!$B$2:$B$101,Edades!$C$2:$C$101)))} -> #NAME? | K35: =IFERROR(__xludf.DUMMYFUNCTION("index(query(importjson(E35)),2,)"),"114228") -> 114228 | L35: =IFERROR(__xludf.DUMMYFUNCTION("""COMPUTED_VALUE"""),"2025") -> 2025 | M35: =IFERROR(__xludf.DUMMYFUNCTION("""COMPUTED_VALUE"""),"32048") -> 32048 | N35: =IFERROR(__xludf.DUMMYFUNCTION("""COMPUTED_VALUE"""),"Olympic Oval Finale - Team Sprint") -> Olympic Oval Finale - Team Sprint | O35: =IFERROR(__xludf.DUMMYFUNCTION("""COMPUTED_VALUE"""),"2026-03-15") -> 2026-03-15 | P35: =IFERROR(__xludf.DUMMYFUNCTION("""COMPUTED_VALUE"""),"2026-03-15") -> 2026-03-15 | Q35: =IFERROR(__xludf.DUMMYFUNCTION("""COMPUTED_VALUE"""),"Calgary (CAN)") -> Calgary (CAN) | R35: =IFERROR(__xludf.DUMMYFUNCTION("""COMPUTED_VALUE"""),"5") -> 5 | S35: =IFERROR(__xludf.DUMMYFUNCTION("""COMPUTED_VALUE"""),"http://speedskatingresults.com/index.php?p=2&e=32048&s=114228") -> http://speedskatingresults.com/index.php?p=2&e=32048&s=114228
C36: =#REF! -> #REF! | D36: =#REF! -> #REF! | E36: =CONCATENATE("https://speedskatingresults.com/api/json/skater_competitions?skater=",D36,"&season=",$B$6) -> #REF! | F36: =IF(ISBLANK(N36)," ",IF( YEARFRAC(G36,CONCATENATE("31/12/",YEAR(G36)),1)>0.502, ROUND(YEARFRAC(CONCATENATE("31/12/",YEAR(G36)-1),IF( YEARFRAC(H36,CONCATENATE("31/12/",YEAR(H36)),1)>0.502, CONCATENATE("31/12/",YEAR(H36)-1), CONCATENATE("31/12/",YEAR(H36)) ),1),0), ROUND(YEARFRAC(CONCATENATE("31/12/",YEAR(G36)),IF( YEARFRAC(H36,CONCATENATE("31/12/",YEAR(H36)),1)>0.502, CONCATENATE("31/12/",YEAR(H36)-1), CONCATENATE("31/12/",YEAR(H36)) ),1),0) )) -> #NAME? | G36: {=IF(ISBLANK(N36)," ",_xlfn.XLOOKUP(D36,#REF!,#REF!))} -> #NAME? | H36: =O36 -> 2026-01-09 | I36: {=IF(ISBLANK(K36)," ",_xlfn.XLOOKUP(D36,#REF!,#REF!))} -> #NAME? | J36: {=IF(ISBLANK(N36)," ",_xlfn.XLOOKUP(F36,Edades!$A$2:$A$101,IF(I36="F",Edades!$B$2:$B$101,Edades!$C$2:$C$101)))} -> #NAME? | K36: =IFERROR(__xludf.DUMMYFUNCTION("index(query(importjson(E36)),2,)"),"64097") -> 64097 | L36: =IFERROR(__xludf.DUMMYFUNCTION("""COMPUTED_VALUE"""),"2025") -> 2025 | M36: =IFERROR(__xludf.DUMMYFUNCTION("""COMPUTED_VALUE"""),"31248") -> 31248 | N36: =IFERROR(__xludf.DUMMYFUNCTION("""COMPUTED_VALUE"""),"ISU European Speed Skating Championships 2026") -> ISU European Speed Skating Championships 2026 | O36: =IFERROR(__xludf.DUMMYFUNCTION("""COMPUTED_VALUE"""),"2026-01-09") -> 2026-01-09 | P36: =IFERROR(__xludf.DUMMYFUNCTION("""COMPUTED_VALUE"""),"2026-01-11") -> 2026-01-11 | Q36: =IFERROR(__xludf.DUMMYFUNCTION("""COMPUTED_VALUE"""),"Tomaszów-Mazowiecki (POL)") -> Tomaszów-Mazowiecki (POL) | R36: =IFERROR(__xludf.DUMMYFUNCTION("""COMPUTED_VALUE"""),"58") -> 58 | S36: =IFERROR(__xludf.DUMMYFUNCTION("""COMPUTED_VALUE"""),"http://speedskatingresults.com/index.php?p=2&e=31248&s=64097") -> http://speedskatingresults.com/index.php?p=2&e=31248&s=64097
C37: =#REF! -> #REF! | D37: =#REF! -> #REF! | E37: =CONCATENATE("https://speedskatingresults.com/api/json/skater_competitions?skater=",D37,"&season=",$B$6) -> #REF! | F37: =IF(ISBLANK(N37)," ",IF( YEARFRAC(G37,CONCATENATE("31/12/",YEAR(G37)),1)>0.502, ROUND(YEARFRAC(CONCATENATE("31/12/",YEAR(G37)-1),IF( YEARFRAC(H37,CONCATENATE("31/12/",YEAR(H37)),1)>0.502, CONCATENATE("31/12/",YEAR(H37)-1), CONCATENATE("31/12/",YEAR(H37)) ),1),0), ROUND(YEARFRAC(CONCATENATE("31/12/",YEAR(G37)),IF( YEARFRAC(H37,CONCATENATE("31/12/",YEAR(H37)),1)>0.502, CONCATENATE("31/12/",YEAR(H37)-1), CONCATENATE("31/12/",YEAR(H37)) ),1),0) )) | G37: {=IF(ISBLANK(N37)," ",_xlfn.XLOOKUP(D37,#REF!,#REF!))} | H37: =O37 -> 0 | I37: {=IF(ISBLANK(K37)," ",_xlfn.XLOOKUP(D37,#REF!,#REF!))} | J37: {=IF(ISBLANK(N37)," ",_xlfn.XLOOKUP(F37,Edades!$A$2:$A$101,IF(I37="F",Edades!$B$2:$B$101,Edades!$C$2:$C$101)))}
C38: =#REF! -> #REF! | D38: =#REF! -> #REF! | E38: =CONCATENATE("https://speedskatingresults.com/api/json/skater_competitions?skater=",D38,"&season=",$B$6) -> #REF! | F38: =IF(ISBLANK(N38)," ",IF( YEARFRAC(G38,CONCATENATE("31/12/",YEAR(G38)),1)>0.502, ROUND(YEARFRAC(CONCATENATE("31/12/",YEAR(G38)-1),IF( YEARFRAC(H38,CONCATENATE("31/12/",YEAR(H38)),1)>0.502, CONCATENATE("31/12/",YEAR(H38)-1), CONCATENATE("31/12/",YEAR(H38)) ),1),0), ROUND(YEARFRAC(CONCATENATE("31/12/",YEAR(G38)),IF( YEARFRAC(H38,CONCATENATE("31/12/",YEAR(H38)),1)>0.502, CONCATENATE("31/12/",YEAR(H38)-1), CONCATENATE("31/12/",YEAR(H38)) ),1),0) )) | G38: {=IF(ISBLANK(N38)," ",_xlfn.XLOOKUP(D38,#REF!,#REF!))} | H38: =O38 -> 0 | I38: {=IF(ISBLANK(K38)," ",_xlfn.XLOOKUP(D38,#REF!,#REF!))} | J38: {=IF(ISBLANK(N38)," ",_xlfn.XLOOKUP(F38,Edades!$A$2:$A$101,IF(I38="F",Edades!$B$2:$B$101,Edades!$C$2:$C$101)))}
C39: =#REF! -> #REF! | D39: =#REF! -> #REF! | E39: =CONCATENATE("https://speedskatingresults.com/api/json/skater_competitions?skater=",D39,"&season=",$B$6) -> #REF! | F39: =IF(ISBLANK(N39)," ",IF( YEARFRAC(G39,CONCATENATE("31/12/",YEAR(G39)),1)>0.502, ROUND(YEARFRAC(CONCATENATE("31/12/",YEAR(G39)-1),IF( YEARFRAC(H39,CONCATENATE("31/12/",YEAR(H39)),1)>0.502, CONCATENATE("31/12/",YEAR(H39)-1), CONCATENATE("31/12/",YEAR(H39)) ),1),0), ROUND(YEARFRAC(CONCATENATE("31/12/",YEAR(G39)),IF( YEARFRAC(H39,CONCATENATE("31/12/",YEAR(H39)),1)>0.502, CONCATENATE("31/12/",YEAR(H39)-1), CONCATENATE("31/12/",YEAR(H39)) ),1),0) )) | G39: {=IF(ISBLANK(N39)," ",_xlfn.XLOOKUP(D39,#REF!,#REF!))} | H39: =O39 -> 0 | I39: {=IF(ISBLANK(K39)," ",_xlfn.XLOOKUP(D39,#REF!,#REF!))} | J39: {=IF(ISBLANK(N39)," ",_xlfn.XLOOKUP(F39,Edades!$A$2:$A$101,IF(I39="F",Edades!$B$2:$B$101,Edades!$C$2:$C$101)))}
C40: =#REF! -> #REF! | D40: =#REF! -> #REF! | E40: =CONCATENATE("https://speedskatingresults.com/api/json/skater_competitions?skater=",D40,"&season=",$B$6) -> #REF! | F40: =IF(ISBLANK(N40)," ",IF( YEARFRAC(G40,CONCATENATE("31/12/",YEAR(G40)),1)>0.502, ROUND(YEARFRAC(CONCATENATE("31/12/",YEAR(G40)-1),IF( YEARFRAC(H40,CONCATENATE("31/12/",YEAR(H40)),1)>0.502, CONCATENATE("31/12/",YEAR(H40)-1), CONCATENATE("31/12/",YEAR(H40)) ),1),0), ROUND(YEARFRAC(CONCATENATE("31/12/",YEAR(G40)),IF( YEARFRAC(H40,CONCATENATE("31/12/",YEAR(H40)),1)>0.502, CONCATENATE("31/12/",YEAR(H40)-1), CONCATENATE("31/12/",YEAR(H40)) ),1),0) )) | G40: {=IF(ISBLANK(N40)," ",_xlfn.XLOOKUP(D40,#REF!,#REF!))} | H40: =O40 -> 0 | I40: {=IF(ISBLANK(K40)," ",_xlfn.XLOOKUP(D40,#REF!,#REF!))} | J40: {=IF(ISBLANK(N40)," ",_xlfn.XLOOKUP(F40,Edades!$A$2:$A$101,IF(I40="F",Edades!$B$2:$B$101,Edades!$C$2:$C$101)))}
...

Sheet Letra Inicial
A1: Primera Letra
A2: A
A3: B
A4: C
A5: D
A6: E
A7: F
A8: G
A9: H
A10: I
A11: J
A12: K
... A27: Z

Sheet Pistas
A1: Nombre | B1: País | C1: Id. Pista
A2: Adavere | B2: EST | C2: 99
A3: Akan | B3: JPN | C3: 125
A4: Alkmaar | B4: NED | C4: 72
A5: Almaty | B5: KAZ | C5: 13
A6: Alta | B6: NOR | C6: 247
A7: Ammerstol | B7: NED | C7: 163
A8: Amsterdam | B8: NED | C8: 118
A9: Amsterdam-Olympic | B9: NED | C9: 244
A10: Anchorage | B10: USA | C10: 183
A11: Arendal | B11: NOR | C11: 94
A12: Arkhangelsk-Dinamo | B12: RUS | C12: 272
A13: Arkhangelsk-Trud | B13: RUS | C13: 160
... A274: Žďár nad Sázavou | B274: CZE | C274: 199

Sheet Categorías_SP
A1: Categoría | B1: Sexo
A2: Absoluta | B2: F
A3: JR | B3: M
A4: C
A5: C1
A6: C2
A7: B
A8: B1
A9: B2
A10: A
A11: A1
A12: A2
A13: N
A14: N1
A15: N2
... A27: M
A28: 30
A29: 35
A30: 40
A31: 45
A32: 50
A33: 55
A34: 60
A35: 65
A36: 70
A37: 75
A38: 80
A39: 85
... A42: 0

Sheet Categorías
A1: Categoría | B1: Aux cadena
A2: Absoluta | B2: =CONCATENATE(C3:Q11) -> #VALUE!
A3: Youth | B3: =CONCATENATE(C3:Q3) -> #VALUE! | C3: YA | D3: YB | E3: YC | F3: YD | G3: YE | H3: YF
A4: Júnior | B4: =CONCATENATE(C4:Q4) -> #VALUE! | C4: A1 | D4: A2 | E4: B1 | F4: B2 | G4: C1 | H4: C2
A5: JA | B5: =CONCATENATE(C5:Q5) -> #VALUE! | C5: A1 | D5: A2
A6: JB | B6: =CONCATENATE(C6:Q6) -> #VALUE! | C6: B1 | D6: B2
A7: JC | B7: =CONCATENATE(C7:Q7) -> #VALUE! | C7: C1 | D7: C2
A8: Neo | B8: =CONCATENATE(C8:Q8) -> #VALUE! | C8: N1 | D8: N2 | E8: N3 | F8: N4
A9: Sénior | B9: =CONCATENATE(C9:Q9) -> #VALUE! | C9: SA
A10: Sénior + Neo | B10: =CONCATENATE(C10:Q10) -> #VALUE! | C10: SA | D10: N1 | E10: N2 | F10: N3 | G10: N4
A11: Máster | B11: =CONCATENATE(C11:Q11) -> #VALUE! | C11: 30 | D11: 35 | E11: 40 | F11: 45 | G11: 50 | H11: 55 | I11: 60 | J11: 65 | K11: 70 | L11: 75 | M11: 80 | N11: 85 | O11: 90 | P11: 95 | Q11: 00

Sheet Distancias
B1: Distancias
B2: 100
B3: 300
B4: 500
B5: 1000
B6: 1500
B7: 3000
B8: 5000
B9: 10000

Sheet Edades
A1: Edad | B1: CaT-F | C1: CaT-M
A2: 100 | B2: L+ | C2: M+
A3: 99 | B3: L+ | C3: M+
A4: 98 | B4: L+ | C4: M+
A5: 97 | B5: L+ | C5: M+
A6: 96 | B6: L+ | C6: M+
A7: 95 | B7: L+ | C7: M+
A8: 94 | B8: L+ | C8: M+
A9: 93 | B9: L+ | C9: M+
A10: 92 | B10: L+ | C10: M+
A11: 91 | B11: L+ | C11: M+
A12: 90 | B12: L+ | C12: M+
A13: 89 | B13: L+ | C13: M+
... A101: 1 | B101: LYF | C101: MYF
